[2025-03-23 22:11:22,411] INFO 172.22.0.1 - - [23/Mar/2025 22:11:22] "[35m[1mGET /openapi/swagger HTTP/1.1[0m" 500 - - call_trace=/usr/local/lib/python3.12/site-packages/werkzeug/_internal.py L97  
[2025-03-23 22:11:22,419] ERROR Error on request:
Traceback (most recent call last):
  File "/usr/local/lib/python3.12/site-packages/werkzeug/serving.py", line 370, in run_wsgi
    execute(self.server.app)
  File "/usr/local/lib/python3.12/site-packages/werkzeug/serving.py", line 331, in execute
    application_iter = app(environ, start_response)
                       ^^^^^^^^^^^^^^^^^^^^^^^^^^^^
  File "/usr/local/lib/python3.12/site-packages/flask/cli.py", line 972, in app
    raise err from None
  File "/usr/local/lib/python3.12/site-packages/flask/cli.py", line 961, in run_command
    app: WSGIApplication = info.load_app()  # pyright: ignore
                           ^^^^^^^^^^^^^^^^^^^^^^^^^^^^^^^^^^
  File "/usr/local/lib/python3.12/site-packages/flask/cli.py", line 349, in load_app
    app = locate_app(import_name, name)
          ^^^^^^^^^^^^^^^^^^^^^^^^^^^^^
  File "/usr/local/lib/python3.12/site-packages/flask/cli.py", line 245, in locate_app
    __import__(module_name)
  File "/app/app.py", line 212, in <module>
    @app.get('/convert-currency', tags=["Currency Conversion"],
     ^^^^^^^^^^^^^^^^^^^^^^^^^^^^^^^^^^^^^^^^^^^^^^^^^^^^^^^^^^
  File "/usr/local/lib/python3.12/site-packages/flask_openapi3/scaffold.py", line 163, in decorator
    self._collect_openapi_info(
  File "/usr/local/lib/python3.12/site-packages/flask_openapi3/openapi.py", line 427, in _collect_openapi_info
    parse_and_store_tags(tags, self.tags, self.tag_names, operation)
  File "/usr/local/lib/python3.12/site-packages/flask_openapi3/utils.py", line 384, in parse_and_store_tags
    if tag.name not in old_tag_names:
       ^^^^^^^^^^^^^^^^^^^^^^^^^^^^^^
AttributeError: 'str' object has no attribute 'name' - call_trace=/usr/local/lib/python3.12/site-packages/werkzeug/_internal.py L97  
[2025-03-23 22:11:22,439] INFO 172.22.0.1 - - [23/Mar/2025 22:11:22] "[35m[1mGET /favicon.ico HTTP/1.1[0m" 500 - - call_trace=/usr/local/lib/python3.12/site-packages/werkzeug/_internal.py L97  
[2025-03-23 22:11:22,442] ERROR Error on request:
Traceback (most recent call last):
  File "/usr/local/lib/python3.12/site-packages/werkzeug/serving.py", line 370, in run_wsgi
    execute(self.server.app)
  File "/usr/local/lib/python3.12/site-packages/werkzeug/serving.py", line 331, in execute
    application_iter = app(environ, start_response)
                       ^^^^^^^^^^^^^^^^^^^^^^^^^^^^
  File "/usr/local/lib/python3.12/site-packages/flask/cli.py", line 972, in app
    raise err from None
  File "/usr/local/lib/python3.12/site-packages/werkzeug/serving.py", line 370, in run_wsgi
    execute(self.server.app)
  File "/usr/local/lib/python3.12/site-packages/werkzeug/serving.py", line 331, in execute
    application_iter = app(environ, start_response)
                       ^^^^^^^^^^^^^^^^^^^^^^^^^^^^
  File "/usr/local/lib/python3.12/site-packages/flask/cli.py", line 972, in app
    raise err from None
  File "/usr/local/lib/python3.12/site-packages/flask/cli.py", line 961, in run_command
    app: WSGIApplication = info.load_app()  # pyright: ignore
                           ^^^^^^^^^^^^^^^^^^^^^^^^^^^^^^^^^^
  File "/usr/local/lib/python3.12/site-packages/flask/cli.py", line 349, in load_app
    app = locate_app(import_name, name)
          ^^^^^^^^^^^^^^^^^^^^^^^^^^^^^
  File "/usr/local/lib/python3.12/site-packages/flask/cli.py", line 245, in locate_app
    __import__(module_name)
  File "/app/app.py", line 212, in <module>
    @app.get('/convert-currency', tags=["Currency Conversion"],
     ^^^^^^^^^^^^^^^^^^^^^^^^^^^^^^^^^^^^^^^^^^^^^^^^^^^^^^^^^^
  File "/usr/local/lib/python3.12/site-packages/flask_openapi3/scaffold.py", line 163, in decorator
    self._collect_openapi_info(
  File "/usr/local/lib/python3.12/site-packages/flask_openapi3/openapi.py", line 427, in _collect_openapi_info
    parse_and_store_tags(tags, self.tags, self.tag_names, operation)
  File "/usr/local/lib/python3.12/site-packages/flask_openapi3/utils.py", line 384, in parse_and_store_tags
    if tag.name not in old_tag_names:
       ^^^^^^^^^^^^^^^^^^^^^^^^^^^^^^
AttributeError: 'str' object has no attribute 'name' - call_trace=/usr/local/lib/python3.12/site-packages/werkzeug/_internal.py L97  
[2025-03-23 22:11:24,638] INFO 172.22.0.1 - - [23/Mar/2025 22:11:24] "[35m[1mGET /openapi/swagger HTTP/1.1[0m" 500 - - call_trace=/usr/local/lib/python3.12/site-packages/werkzeug/_internal.py L97  
[2025-03-23 22:11:24,641] ERROR Error on request:
Traceback (most recent call last):
  File "/usr/local/lib/python3.12/site-packages/werkzeug/serving.py", line 370, in run_wsgi
    execute(self.server.app)
  File "/usr/local/lib/python3.12/site-packages/werkzeug/serving.py", line 331, in execute
    application_iter = app(environ, start_response)
                       ^^^^^^^^^^^^^^^^^^^^^^^^^^^^
  File "/usr/local/lib/python3.12/site-packages/flask/cli.py", line 972, in app
    raise err from None
  File "/usr/local/lib/python3.12/site-packages/werkzeug/serving.py", line 370, in run_wsgi
    execute(self.server.app)
  File "/usr/local/lib/python3.12/site-packages/werkzeug/serving.py", line 331, in execute
    application_iter = app(environ, start_response)
                       ^^^^^^^^^^^^^^^^^^^^^^^^^^^^
  File "/usr/local/lib/python3.12/site-packages/flask/cli.py", line 972, in app
    raise err from None
  File "/usr/local/lib/python3.12/site-packages/werkzeug/serving.py", line 370, in run_wsgi
    execute(self.server.app)
  File "/usr/local/lib/python3.12/site-packages/werkzeug/serving.py", line 331, in execute
    application_iter = app(environ, start_response)
                       ^^^^^^^^^^^^^^^^^^^^^^^^^^^^
  File "/usr/local/lib/python3.12/site-packages/flask/cli.py", line 972, in app
    raise err from None
  File "/usr/local/lib/python3.12/site-packages/flask/cli.py", line 961, in run_command
    app: WSGIApplication = info.load_app()  # pyright: ignore
                           ^^^^^^^^^^^^^^^^^^^^^^^^^^^^^^^^^^
  File "/usr/local/lib/python3.12/site-packages/flask/cli.py", line 349, in load_app
    app = locate_app(import_name, name)
          ^^^^^^^^^^^^^^^^^^^^^^^^^^^^^
  File "/usr/local/lib/python3.12/site-packages/flask/cli.py", line 245, in locate_app
    __import__(module_name)
  File "/app/app.py", line 212, in <module>
    @app.get('/convert-currency', tags=["Currency Conversion"],
     ^^^^^^^^^^^^^^^^^^^^^^^^^^^^^^^^^^^^^^^^^^^^^^^^^^^^^^^^^^
  File "/usr/local/lib/python3.12/site-packages/flask_openapi3/scaffold.py", line 163, in decorator
    self._collect_openapi_info(
  File "/usr/local/lib/python3.12/site-packages/flask_openapi3/openapi.py", line 427, in _collect_openapi_info
    parse_and_store_tags(tags, self.tags, self.tag_names, operation)
  File "/usr/local/lib/python3.12/site-packages/flask_openapi3/utils.py", line 384, in parse_and_store_tags
    if tag.name not in old_tag_names:
       ^^^^^^^^^^^^^^^^^^^^^^^^^^^^^^
AttributeError: 'str' object has no attribute 'name' - call_trace=/usr/local/lib/python3.12/site-packages/werkzeug/_internal.py L97  
[2025-03-23 22:11:24,658] INFO 172.22.0.1 - - [23/Mar/2025 22:11:24] "[35m[1mGET /favicon.ico HTTP/1.1[0m" 500 - - call_trace=/usr/local/lib/python3.12/site-packages/werkzeug/_internal.py L97  
