[2025-03-23 22:09:06,104] INFO  * Restarting with stat - call_trace=/usr/local/lib/python3.12/site-packages/werkzeug/_internal.py L97  
[2025-03-23 22:09:52,042] INFO  * Detected change in '/app/schemas/saving_goal.py', reloading - call_trace=/usr/local/lib/python3.12/site-packages/werkzeug/_internal.py L97  
[2025-03-23 22:09:52,181] INFO  * Restarting with stat - call_trace=/usr/local/lib/python3.12/site-packages/werkzeug/_internal.py L97  
[2025-03-23 22:10:15,013] INFO  * Detected change in '/app/schemas/saving_goal.py', reloading - call_trace=/usr/local/lib/python3.12/site-packages/werkzeug/_internal.py L97  
[2025-03-23 22:10:15,206] INFO  * Restarting with stat - call_trace=/usr/local/lib/python3.12/site-packages/werkzeug/_internal.py L97  
[2025-03-23 22:10:37,053] INFO  * Detected change in '/app/app.py', reloading - call_trace=/usr/local/lib/python3.12/site-packages/werkzeug/_internal.py L97  
[2025-03-23 22:10:37,174] INFO  * Restarting with stat - call_trace=/usr/local/lib/python3.12/site-packages/werkzeug/_internal.py L97  
[2025-03-23 22:10:46,553] INFO  * Detected change in '/app/services/yahoo_finance.py', reloading - call_trace=/usr/local/lib/python3.12/site-packages/werkzeug/_internal.py L97  
[2025-03-23 22:10:46,619] INFO  * Restarting with stat - call_trace=/usr/local/lib/python3.12/site-packages/werkzeug/_internal.py L97  
[2025-03-23 22:10:49,863] INFO 172.22.0.1 - - [23/Mar/2025 22:10:49] "[35m[1mGET /openapi/swagger HTTP/1.1[0m" 500 - - call_trace=/usr/local/lib/python3.12/site-packages/werkzeug/_internal.py L97  
[2025-03-23 22:10:49,874] ERROR Error on request:
Traceback (most recent call last):
  File "/usr/local/lib/python3.12/site-packages/werkzeug/serving.py", line 370, in run_wsgi
    execute(self.server.app)
  File "/usr/local/lib/python3.12/site-packages/werkzeug/serving.py", line 331, in execute
    application_iter = app(environ, start_response)
                       ^^^^^^^^^^^^^^^^^^^^^^^^^^^^
  File "/usr/local/lib/python3.12/site-packages/flask/cli.py", line 972, in app
    raise err from None
  File "/usr/local/lib/python3.12/site-packages/flask/cli.py", line 961, in run_command
    app: WSGIApplication = info.load_app()  # pyright: ignore
                           ^^^^^^^^^^^^^^^^^^^^^^^^^^^^^^^^^^
  File "/usr/local/lib/python3.12/site-packages/flask/cli.py", line 349, in load_app
    app = locate_app(import_name, name)
          ^^^^^^^^^^^^^^^^^^^^^^^^^^^^^
  File "/usr/local/lib/python3.12/site-packages/flask/cli.py", line 250, in locate_app
    raise NoAppException(
flask.cli.NoAppException: While importing 'app', an ImportError was raised:

Traceback (most recent call last):
  File "/usr/local/lib/python3.12/site-packages/flask/cli.py", line 245, in locate_app
    __import__(module_name)
  File "/app/app.py", line 11, in <module>
    from schemas.saving_goal import SavingGoalViewSchema, SavingGoalSchema, SavingGoalsListSchema, SavingGoalSearchSchema, \
ImportError: cannot import name 'ConversionRequest' from 'schemas.saving_goal' (/app/schemas/saving_goal.py) - call_trace=/usr/local/lib/python3.12/site-packages/werkzeug/_internal.py L97  
[2025-03-23 22:10:49,896] INFO 172.22.0.1 - - [23/Mar/2025 22:10:49] "[35m[1mGET /favicon.ico HTTP/1.1[0m" 500 - - call_trace=/usr/local/lib/python3.12/site-packages/werkzeug/_internal.py L97  
[2025-03-23 22:10:49,898] ERROR Error on request:
Traceback (most recent call last):
  File "/usr/local/lib/python3.12/site-packages/werkzeug/serving.py", line 370, in run_wsgi
    execute(self.server.app)
  File "/usr/local/lib/python3.12/site-packages/werkzeug/serving.py", line 331, in execute
    application_iter = app(environ, start_response)
                       ^^^^^^^^^^^^^^^^^^^^^^^^^^^^
  File "/usr/local/lib/python3.12/site-packages/flask/cli.py", line 972, in app
    raise err from None
  File "/usr/local/lib/python3.12/site-packages/werkzeug/serving.py", line 370, in run_wsgi
    execute(self.server.app)
  File "/usr/local/lib/python3.12/site-packages/werkzeug/serving.py", line 331, in execute
    application_iter = app(environ, start_response)
                       ^^^^^^^^^^^^^^^^^^^^^^^^^^^^
  File "/usr/local/lib/python3.12/site-packages/flask/cli.py", line 972, in app
    raise err from None
  File "/usr/local/lib/python3.12/site-packages/flask/cli.py", line 961, in run_command
    app: WSGIApplication = info.load_app()  # pyright: ignore
                           ^^^^^^^^^^^^^^^^^^^^^^^^^^^^^^^^^^
  File "/usr/local/lib/python3.12/site-packages/flask/cli.py", line 349, in load_app
    app = locate_app(import_name, name)
          ^^^^^^^^^^^^^^^^^^^^^^^^^^^^^
  File "/usr/local/lib/python3.12/site-packages/flask/cli.py", line 250, in locate_app
    raise NoAppException(
flask.cli.NoAppException: While importing 'app', an ImportError was raised:

Traceback (most recent call last):
  File "/usr/local/lib/python3.12/site-packages/flask/cli.py", line 245, in locate_app
    __import__(module_name)
  File "/app/app.py", line 11, in <module>
    from schemas.saving_goal import SavingGoalViewSchema, SavingGoalSchema, SavingGoalsListSchema, SavingGoalSearchSchema, \
ImportError: cannot import name 'ConversionRequest' from 'schemas.saving_goal' (/app/schemas/saving_goal.py) - call_trace=/usr/local/lib/python3.12/site-packages/werkzeug/_internal.py L97  
[2025-03-23 22:11:08,061] INFO  * Detected change in '/app/app.py', reloading - call_trace=/usr/local/lib/python3.12/site-packages/werkzeug/_internal.py L97  
[2025-03-23 22:11:08,138] INFO  * Restarting with stat - call_trace=/usr/local/lib/python3.12/site-packages/werkzeug/_internal.py L97  
[2025-03-23 22:11:11,815] INFO 172.22.0.1 - - [23/Mar/2025 22:11:11] "[35m[1mGET /openapi/swagger HTTP/1.1[0m" 500 - - call_trace=/usr/local/lib/python3.12/site-packages/werkzeug/_internal.py L97  
[2025-03-23 22:11:11,833] ERROR Error on request:
Traceback (most recent call last):
  File "/usr/local/lib/python3.12/site-packages/werkzeug/serving.py", line 370, in run_wsgi
    execute(self.server.app)
  File "/usr/local/lib/python3.12/site-packages/werkzeug/serving.py", line 331, in execute
    application_iter = app(environ, start_response)
                       ^^^^^^^^^^^^^^^^^^^^^^^^^^^^
  File "/usr/local/lib/python3.12/site-packages/flask/cli.py", line 972, in app
    raise err from None
  File "/usr/local/lib/python3.12/site-packages/flask/cli.py", line 961, in run_command
    app: WSGIApplication = info.load_app()  # pyright: ignore
                           ^^^^^^^^^^^^^^^^^^^^^^^^^^^^^^^^^^
  File "/usr/local/lib/python3.12/site-packages/flask/cli.py", line 349, in load_app
    app = locate_app(import_name, name)
          ^^^^^^^^^^^^^^^^^^^^^^^^^^^^^
  File "/usr/local/lib/python3.12/site-packages/flask/cli.py", line 250, in locate_app
    raise NoAppException(
flask.cli.NoAppException: While importing 'app', an ImportError was raised:

Traceback (most recent call last):
  File "/usr/local/lib/python3.12/site-packages/flask/cli.py", line 245, in locate_app
    __import__(module_name)
  File "/app/app.py", line 11, in <module>
    from schemas.saving_goal import SavingGoalViewSchema, SavingGoalSchema, SavingGoalsListSchema, SavingGoalSearchSchema, \
ImportError: cannot import name 'ConversionRequest' from 'schemas.saving_goal' (/app/schemas/saving_goal.py) - call_trace=/usr/local/lib/python3.12/site-packages/werkzeug/_internal.py L97  
[2025-03-23 22:11:11,856] INFO 172.22.0.1 - - [23/Mar/2025 22:11:11] "[35m[1mGET /favicon.ico HTTP/1.1[0m" 500 - - call_trace=/usr/local/lib/python3.12/site-packages/werkzeug/_internal.py L97  
[2025-03-23 22:11:11,859] ERROR Error on request:
Traceback (most recent call last):
  File "/usr/local/lib/python3.12/site-packages/werkzeug/serving.py", line 370, in run_wsgi
    execute(self.server.app)
  File "/usr/local/lib/python3.12/site-packages/werkzeug/serving.py", line 331, in execute
    application_iter = app(environ, start_response)
                       ^^^^^^^^^^^^^^^^^^^^^^^^^^^^
  File "/usr/local/lib/python3.12/site-packages/flask/cli.py", line 972, in app
    raise err from None
  File "/usr/local/lib/python3.12/site-packages/werkzeug/serving.py", line 370, in run_wsgi
    execute(self.server.app)
  File "/usr/local/lib/python3.12/site-packages/werkzeug/serving.py", line 331, in execute
    application_iter = app(environ, start_response)
                       ^^^^^^^^^^^^^^^^^^^^^^^^^^^^
  File "/usr/local/lib/python3.12/site-packages/flask/cli.py", line 972, in app
    raise err from None
  File "/usr/local/lib/python3.12/site-packages/flask/cli.py", line 961, in run_command
    app: WSGIApplication = info.load_app()  # pyright: ignore
                           ^^^^^^^^^^^^^^^^^^^^^^^^^^^^^^^^^^
  File "/usr/local/lib/python3.12/site-packages/flask/cli.py", line 349, in load_app
    app = locate_app(import_name, name)
          ^^^^^^^^^^^^^^^^^^^^^^^^^^^^^
  File "/usr/local/lib/python3.12/site-packages/flask/cli.py", line 250, in locate_app
    raise NoAppException(
flask.cli.NoAppException: While importing 'app', an ImportError was raised:

Traceback (most recent call last):
  File "/usr/local/lib/python3.12/site-packages/flask/cli.py", line 245, in locate_app
    __import__(module_name)
  File "/app/app.py", line 11, in <module>
    from schemas.saving_goal import SavingGoalViewSchema, SavingGoalSchema, SavingGoalsListSchema, SavingGoalSearchSchema, \
ImportError: cannot import name 'ConversionRequest' from 'schemas.saving_goal' (/app/schemas/saving_goal.py) - call_trace=/usr/local/lib/python3.12/site-packages/werkzeug/_internal.py L97  
[2025-03-23 22:11:21,521] INFO  * Detected change in '/app/app.py', reloading - call_trace=/usr/local/lib/python3.12/site-packages/werkzeug/_internal.py L97  
[2025-03-23 22:11:21,618] INFO  * Restarting with stat - call_trace=/usr/local/lib/python3.12/site-packages/werkzeug/_internal.py L97  
